# Logfile created on 2020-10-05 17:39:35 +0000 by logger.rb/66358
{"severity":"ERROR","time":"2020-10-05T17:39:35.972Z","correlation_id":"583c1403fac68f50219a3368297872c5","exception.class":"Gitlab::Git::PreReceiveError","exception.message":"Internal API unreachable","exception.backtrace":["lib/gitlab/gitaly_client/operation_service.rb:344:in `user_commit_files'","lib/gitlab/git/repository.rb:883:in `block in multi_action'","lib/gitlab/git/wraps_gitaly_errors.rb:7:in `wrapped_gitaly_errors'","lib/gitlab/git/repository.rb:882:in `multi_action'","app/models/repository.rb:850:in `block in multi_action'","app/models/repository.rb:833:in `with_cache_hooks'","app/models/repository.rb:850:in `multi_action'","app/models/repository.rb:814:in `create_file'","app/services/files/create_service.rb:16:in `create_transformed_commit'","app/services/files/create_service.rb:10:in `create_commit!'","app/services/commits/create_service.rb:30:in `execute'","app/services/projects/create_service.rb:152:in `create_readme'","app/services/projects/create_service.rb:109:in `after_create_actions'","app/services/projects/create_service.rb:59:in `block in execute'","lib/gitlab/application_context.rb:52:in `block in use'","lib/gitlab/application_context.rb:52:in `use'","lib/gitlab/application_context.rb:20:in `with_context'","app/services/projects/create_service.rb:58:in `execute'","app/services/concerns/measurable.rb:35:in `execute'","lib/gitlab/database_importers/self_monitoring/project/create_service.rb:59:in `create_project'","app/models/concerns/stepable.rb:14:in `call'","app/models/concerns/stepable.rb:14:in `block in execute_steps'","app/models/concerns/stepable.rb:13:in `each'","app/models/concerns/stepable.rb:13:in `inject'","app/models/concerns/stepable.rb:13:in `execute_steps'","lib/gitlab/database_importers/self_monitoring/project/create_service.rb:27:in `execute'","(eval):3:in `block (2 levels) in run_file'","lib/tasks/gitlab/db.rake:59:in `block (3 levels) in \u003ctop (required)\u003e'"]}
